<?xml version="1.0" ?>
<!-- =================================================================================== -->
<!-- |    This document was autogenerated by xacro from ic120.xacro                    | -->
<!-- |    EDITING THIS FILE BY HAND IS NOT RECOMMENDED                                 | -->
<!-- =================================================================================== -->
<robot name="ic120">
  <!-- Import Rviz colors -->
  <!-- <xacro:include filename="$(find ic120_description)/urdf/materials.xacro" /> -->
  <!-- Base Link -->
  <link name="base_link"/>
  <joint name="base_joint" type="fixed">
    <parent link="base_link"/>
    <child link="body_link"/>
  </joint>
  <link name="body_link">
    <visual>
      <geometry>
        <mesh filename="package://ic120_description/meshes/ic120-body.dae"/>
      </geometry>
    </visual>
    <inertial>
      <origin rpy="0 0 0" xyz="0.8963 0.1313 1.35"/>
      <mass value="0.1"/>
      <inertia ixx="1.0" ixy="0.0" ixz="0.0" iyy="1.0" iyz="0.0" izz="1.0"/>
    </inertial>
  </link>
  <!-- left sprocket axis -->
  <joint name="sprocket_left_joint" type="continuous">
    <origin xyz="-2.35 1 0.65"/>
    <axis xyz="0 1 0"/>
    <parent link="body_link"/>
    <child link="left_sprocket_link"/>
  </joint>
  <link name="left_sprocket_link"/>
  <!-- right sprocket axis -->
  <joint name="sprocket_right_joint" type="continuous">
    <origin xyz="-2.35 -1 0.65"/>
    <axis xyz="0 1 0"/>
    <parent link="body_link"/>
    <child link="right_sprocket_link"/>
  </joint>
  <link name="right_sprocket_link"/>
  <!-- bucket axis -->
  <joint name="vessel_pin_joint" type="revolute">
    <origin xyz="-3.0153 0 0.94605"/>
    <axis xyz="0 1 0"/>
    <parent link="body_link"/>
    <child link="vessel_pin_link"/>
    <limit effort="30" lower="-1.1344640137963142" upper="0" velocity="6.159937255"/>
  </joint>
  <link name="vessel_pin_link">
    <visual>
      <geometry>
        <mesh filename="package://ic120_description/meshes/ic120-vessel.dae"/>
      </geometry>
    </visual>
    <inertial>
      <origin rpy="0 0 0" xyz="1.978 0.0181 0.773"/>
      <mass value="0.1"/>
      <inertia ixx="1.0" ixy="0.0" ixz="0.0" iyy="1.0" iyz="0.0" izz="1.0"/>
    </inertial>
  </link>
  <!-- cylinder outer axis -->
  <joint name="cylinder_head_joint" type="continuous">
    <origin xyz="-0.75792 0 0.73083"/>
    <axis xyz="0 1 0"/>
    <parent link="body_link"/>
    <child link="cylinder_head_link"/>
    <mimic joint="vessel_pin_joint" multiplier="-0.088"/>
  </joint>
  <link name="cylinder_head_link">
    <visual>
      <geometry>
        <mesh filename="package://ic120_description/meshes/ic120-cylinder1.dae"/>
      </geometry>
    </visual>
    <inertial>
      <origin rpy="0 0 0" xyz="-0.4842 0 0.1667"/>
      <mass value="0.03"/>
      <inertia ixx="1.0" ixy="0.0" ixz="0.0" iyy="1.0" iyz="0.0" izz="1.0"/>
    </inertial>
  </link>
  <!-- cylinder inner prismatic joint -->
  <joint name="cylinder_rod_prismatic_joint" type="prismatic">
    <origin xyz="0 0 0"/>
    <parent link="cylinder_head_link"/>
    <child link="cylinder_rod_link"/>
    <axis xyz="-1.4989 0 0.51788"/>
    <limit effort="30" lower="-1" upper="1" velocity="6.159937255"/>
    <mimic joint="vessel_pin_joint" multiplier="-0.7051788247763978"/>
  </joint>
  <link name="cylinder_rod_link">
    <visual>
      <geometry>
        <mesh filename="package://ic120_description/meshes/ic120-cylinder2.dae"/>
      </geometry>
    </visual>
    <inertial>
      <origin rpy="0 0 0" xyz="-0.8807 0 0.3033"/>
      <mass value="0.03"/>
      <inertia ixx="1.0" ixy="0.0" ixz="0.0" iyy="1.0" iyz="0.0" izz="1.0"/>
    </inertial>
  </link>
  <transmission name="tran1">
    <type>transmission_interface/SimpleTransmission</type>
    <joint name="vessel_pin_joint">
      <hardwareInterface>hardware_interface/EffortJointInterface</hardwareInterface>
    </joint>
    <actuator name="vessel_pin_joint_motor">
      <hardwareInterface>hardware_interface/EffortJointInterface</hardwareInterface>
      <mechanicalReduction>1</mechanicalReduction>
    </actuator>
  </transmission>
</robot>
